Workbook

Sheet Диплом
A1: Наименование
A2: Учебное заведение | B2: федеральное государственное бюджетное образовательное учреждение высшего образования «Московский государственный психолого-педагогический университет» | C2: Варианты(примеры) значений
A3: Местоположение | B3: г Москва
A4: Приложение | C4: ДУБЛИКАТ
A5: Уровень | B5: бакалавра | C5: бакалавра | D5: бакалавра
A6: С отличием ? | B6: с отличием | C6: с отличием
A7: Регистрационный номер | B7: YYYY/Б24
A8: Дата выдачи | B8: YY июня 2024 года | C8: 30 января 2014 года
A9: Руководитель учебного заведения | B9: А.А. Марголис

Sheet 1 Обладатель диплома
A1: Наименование | B1: Значения | C1: Примеры значений
A2: Личные данные
A3: Фамилия | B3: Фамилия
A4: Имя | B4: Имя
A5: Отчество | B5: Отчество
A6: Дата рождения | B6: 22 января 2005 года | C6: 26 января 1985 года
A7: Предыдущий документ об образовании
A8: Наименование документа | C8: Сверить с документом в дичном деле | D8: Наименование документа об образовании или об образовании и о квалификации, на основании которого выпускник был принят на обучение по ОПОП (аттестат о среднем общем образовании или диплом о начальном профессиональном образовании (полученный до вступления в силу ФЗ), если в нем есть запись о получении среднего общего образования, или диплом о среднем профессиональном образовании, или документ о высшем образовании)
A9: Год выдачи
A10: Сведения о квалификации
A11: Присвоена квалификация | C11: Бакалавр | D11: Бакалавр
A12: с отличием ? | B12: с отличием | C12: с отличием
A14: Код и наименование специальности или направления подготовки
A15: Протокол присвоения квалификации | C15: вписываем протокол ГЭК (как в дипломе)
A16: Срок освоения программы в очной форме обучения
A17: количество лет | C17: 4
A18: год / лет | C18: года
A19: количество месяцев | C19: 2
A20: месяцев / месяца | C20: месяца

Sheet 3 Освоение программы
B1: Наименования дисциплин (модулей), практик, курсовых работ | C1: Количество зачетных единиц / академических часов / астрономических часов | D1: Оценка | E1: ячейка выделена - символов больше 75 - допустимо не больше
A2: 1 | B2: Дисциплина 1 | C2: ?? з.е. | D2: оценка | E2: =LEN(B2) -> 12
A3: 2 | B3: Дисциплина 2 | C3: ?? з.е. | D3: оценка | E3: =LEN(B3) -> 12
A4: 3 | B4: Дисциплина 3 | C4: ?? з.е. | D4: оценка | E4: =LEN(B4) -> 12
A5: 4 | B5: Дисциплина 4 | C5: ?? з.е. | D5: оценка | E5: =LEN(B5) -> 12
A6: 5 | B6: Дисциплина 5 | C6: ?? з.е. | D6: оценка | E6: =LEN(B6) -> 12
A7: 6 | B7: Дисциплина 6 | C7: ?? з.е. | D7: оценка | E7: =LEN(B7) -> 12
A8: 7 | B8: Дисциплина 7 | C8: ?? з.е. | D8: оценка | E8: =LEN(B8) -> 12
A9: 8 | B9: Дисциплина 8 | C9: ?? з.е. | D9: оценка | E9: =LEN(B9) -> 12
A10: 9 | B10: Дисциплина 9 | C10: ?? з.е. | D10: оценка | E10: =LEN(B10) -> 12
A11: 10 | B11: Дисциплина 10 | C11: ?? з.е. | D11: оценка | E11: =LEN(B11) -> 13
A12: 11 | B12: Дисциплина 11 | C12: ?? з.е. | D12: оценка | E12: =LEN(B12) -> 13
A13: 12 | B13: Дисциплина 12 | C13: ?? з.е. | D13: оценка | E13: =LEN(B13) -> 13
... A66: 65 | B66: Дисциплина 65 | C66: ?? з.е. | D66: оценка | E66: =LEN(B66) -> 13
A67: 66 | B67: Дисциплина 66 | C67: ?? з.е. | D67: оценка | E67: =LEN(B67) -> 13 | F67: последняя строка левой таблицы
A68: 67 | B68: Дисциплина 67 | C68: ?? з.е. | D68: оценка | E68: =LEN(B68) -> 13
A69: 68 | B69: Дисциплина 68 | C69: ?? з.е. | D69: оценка | E69: =LEN(B69) -> 13
A70: 69 | B70: Дисциплина 69 | C70: ?? з.е. | D70: оценка | E70: =LEN(B70) -> 13
A71: 70 | B71: Дисциплина 70 | C71: ?? з.е. | D71: оценка | E71: =LEN(B71) -> 13
A72: 71 | B72: Практики | C72: ?? з.е. | D72: x | E72: =LEN(B72) -> 8
A73: 72 | B73: в том числе: | E73: =LEN(B73) -> 12
A74: 73 | B74: Вид практики, тип практики | C74: ?? з.е. | D74: оценка | E74: =LEN(B74) -> 26
A75: 74 | B75: Вид практики, тип практики | C75: ?? з.е. | D75: оценка | E75: =LEN(B75) -> 26
A76: 75 | B76: Вид практики, тип практики | C76: ?? з.е. | D76: оценка | E76: =LEN(B76) -> 26
A77: 76 | B77: Вид практики, тип практики | C77: ?? з.е. | D77: оценка | E77: =LEN(B77) -> 26
A78: 77 | B78: Вид практики, тип практики | C78: ?? з.е. | D78: оценка | E78: =LEN(B78) -> 26
A79: 78 | B79: Государственная итоговая аттестация | C79: ?? з.е. | D79: х | E79: =LEN(B79) -> 35
A80: 79 | B80: в том числе: | E80: =LEN(B80) -> 12
A81: 80 | B81: Выпускная квалификационная работа (бакалаврская работа) | E81: =LEN(B81) -> 56
A82: 81 | B82: "Субъективное благополучие отстающих в обучении | E82: =LEN(B82) -> 47
A83: 82 | B83: младших школьников" | C83: х | D83: оценка | E83: =LEN(B83) -> 19
A84: 83 | B84: Объем образовательной программы | C84: 240 з.е. | D84: х | E84: =LEN(B84) -> 31
A85: 84 | B85: в том числе объем контактной работы обучающихся | E85: =LEN(B85) -> 48
A86: 85 | B86: во взаимодействии с преподавателем в академических часах: | C86: ?? ак. час. | D86: х | E86: =LEN(B86) -> 57
A87: 86 | B87: Наименование дисциплины "Очень длинная и очень итересная | E87: =LEN(B87) -> 58
A88: 87 | B88: тема курсовой работы" | D88: оценка | E88: =LEN(B88) -> 21
A89: 88 | B89: Наименование дисциплины "Очень длинная и очень итересная | E89: =LEN(B89) -> 58
A90: 89 | B90: тема курсовой работы" | D90: оценка | E90: =LEN(B90) -> 21
A91: 90 | B91: Факультативные дисциплины (модули) | E91: =LEN(B91) -> 34
A92: 91 | B92: в том числе: | E92: =LEN(B92) -> 12
...

Sheet 4 доп.сведения
B1: Дополнительные сведения | D1: ячейка выделена - символов больше 95 допустимо не больше
A2: 1 | D2: =LEN(B2) -> 0
A3: 2 | D3: =LEN(B3) -> 0
A4: 3 | D4: =LEN(B4) -> 0
A5: 4 | D5: =LEN(B5) -> 0
A6: 5 | D6: =LEN(B6) -> 0
A7: 6 | D7: =LEN(B7) -> 0
A8: 7 | D8: =LEN(B8) -> 0
A9: 8 | D9: =LEN(B9) -> 0
A10: 9 | D10: =LEN(B10) -> 0
A11: 10 | D11: =LEN(B11) -> 0
A12: 11 | D12: =LEN(B12) -> 0
A13: 12 | D13: =LEN(B13) -> 0
... A40: 39 | D40: =LEN(B40) -> 0
A41: 40 | D41: =LEN(B41) -> 0 | E41: последняя строка таблицы

Sheet 5 Доп сведения
B1: Наименование поля | C1: Значение поля | D1: ячейка выделена - символов больше122 - допустимо не больше
A3: 1 | B3: Дополнительные сведения 1 | C3: Направленность (профиль) образовательной программы: Психология образования | D3: =LEN(C3) -> 74
A4: 2 | B4: Дополнительные сведения 2 | C4: Форма обучения: очная | D4: =LEN(C4) -> 21
A5: 3 | B5: Дополнительные сведения 3 | D5: =LEN(C5) -> 0
A6: 4 | B6: Дополнительные сведения 4 | D6: =LEN(C6) -> 0
A7: 5 | B7: Дополнительные сведения 5 | D7: =LEN(C7) -> 0
A8: 6 | B8: Дополнительные сведения 6 | D8: =LEN(C8) -> 0
A9: 7 | B9: Дополнительные сведения 7 | D9: =LEN(C9) -> 0
B10: Дополнительные сведения 8 | D10: =LEN(C10) -> 0
B11: Дополнительные сведения 9 | D11: =LEN(C11) -> 0
B12: Дополнительные сведения 10 | D12: =LEN(C12) -> 0
B13: Дополнительные сведения 11 | D13: =LEN(C13) -> 0

Sheet  Лицевая 04
C16: =IF(LEN(TRIM('4 доп.сведения'!B2))=0," ",'4 доп.сведения'!B2)
B19: =IF(LEN(TRIM('4 доп.сведения'!B5))=0," ",'4 доп.сведения'!B5)
B22: ='4 доп.сведения'!B6:C6 -> 0
CF23: ='1 Обладатель диплома'!B3 -> Фамилия
B25: ='4 доп.сведения'!B7 -> 0
B34: =IF(LEN(TRIM('4 доп.сведения'!B18))=0," ",'4 доп.сведения'!B18)
CF35: ='1 Обладатель диплома'!B4 -> Имя
B37: =IF(LEN(TRIM('4 доп.сведения'!B21))=0," ",'4 доп.сведения'!B21)
B40: =IF(LEN(TRIM('4 доп.сведения'!B24))=0," ",'4 доп.сведения'!B24)
B43: =IF(LEN(TRIM('4 доп.сведения'!B27))=0," ",'4 доп.сведения'!B27)
BE45: =Диплом!B2 -> федеральное государственное бюджетное образовательное учреждение высшего образования «Московский государственный психолого-педагогический университет»
C46: =IF(LEN(TRIM('4 доп.сведения'!B30))=0," ",'4 доп.сведения'!B30)
C49: =IF(LEN(TRIM('4 доп.сведения'!B33))=0," ",'4 доп.сведения'!B33) | CF49: ='1 Обладатель диплома'!B5 -> Отчество
CF62: ='1 Обладатель диплома'!B6 -> 22 января 2005 года
C70: =IF(LEN(TRIM('4 доп.сведения'!B20))=0," ",'4 доп.сведения'!B20) | BE70: г Москва
C73: =IF(LEN(TRIM('4 доп.сведения'!B21))=0," ",'4 доп.сведения'!B21)
C76: =IF(LEN(TRIM('4 доп.сведения'!B22))=0," ",'4 доп.сведения'!B23)
C79: =IF(LEN(TRIM('4 доп.сведения'!B24))=0," ",'4 доп.сведения'!B24) | BV79: =IF(LEN(TRIM('1 Обладатель диплома'!B8 & " " &'1 Обладатель диплома'!B9))=0," ",'1 Обладатель диплома'!B8 & " " &'1 Обладатель диплома'!B9)
C82: =IF(LEN(TRIM('4 доп.сведения'!B25))=0," ",'4 доп.сведения'!B26)
C85: =IF(LEN(TRIM('4 доп.сведения'!B55))=0," ",'4 доп.сведения'!B55)
BE87: =IF(Диплом!B4=""," ",Диплом!B4)
C88: =IF(LEN(TRIM('4 доп.сведения'!B58))=0," ",'4 доп.сведения'!B58)
D92: =IF(LEN(TRIM('4 доп.сведения'!B35))=0," ",'4 доп.сведения'!B35) | AP92: =IF(LEN(TRIM('4 доп.сведения'!C35))=0," ",'4 доп.сведения'!C35)
D94: =IF(LEN(TRIM('4 доп.сведения'!B36))=0," ",'4 доп.сведения'!B36) | AP94: =IF(LEN(TRIM('4 доп.сведения'!C36))=0," ",'4 доп.сведения'!C36)
D96: =IF(LEN(TRIM('4 доп.сведения'!B37))=0," ",'4 доп.сведения'!B37) | AP96: =IF(LEN(TRIM('4 доп.сведения'!C37))=0," ",'4 доп.сведения'!C37)
D98: =IF(LEN(TRIM('4 доп.сведения'!B38))=0," ",'4 доп.сведения'!B38) | AP98: =IF(LEN(TRIM('4 доп.сведения'!C38))=0," ",'4 доп.сведения'!C38)
D102: =IF(LEN(TRIM('4 доп.сведения'!B39))=0," ",'4 доп.сведения'!B39) | AP102: =IF(LEN(TRIM('4 доп.сведения'!C39))=0," ",'4 доп.сведения'!C39)
D104: =IF(LEN(TRIM('4 доп.сведения'!B40))=0," ",'4 доп.сведения'!B40) | AP104: =IF(LEN(TRIM('4 доп.сведения'!C40))=0," ",'4 доп.сведения'!C40)
D106: =IF(LEN(TRIM('4 доп.сведения'!B41))=0," ",'4 доп.сведения'!B41) | AP106: =IF(LEN(TRIM('4 доп.сведения'!C41))=0," ",'4 доп.сведения'!C41)
D119: =IF(LEN(TRIM('4 доп.сведения'!B59))=0," ",'4 доп.сведения'!B59) | AP119: =IF(LEN(TRIM('4 доп.сведения'!C59))=0," ",'4 доп.сведения'!C59)
BE120: =Диплом!B5&" "&Диплом!B6 -> бакалавра с отличием
D123: =IF(LEN(TRIM('4 доп.сведения'!B60))=0," ",'4 доп.сведения'!B60) | AP123: =IF(LEN(TRIM('4 доп.сведения'!C60))=0," ",'4 доп.сведения'!C60)
D125: =IF(LEN(TRIM('4 доп.сведения'!B61))=0," ",'4 доп.сведения'!B61)
D127: =IF(LEN(TRIM('4 доп.сведения'!B62))=0," ",'4 доп.сведения'!B62)
AD132: =Диплом!B9 -> А.А. Марголис
D135: =IF(LEN(TRIM('4 доп.сведения'!B71))=0," ",'4 доп.сведения'!B71)
D137: =IF(LEN(TRIM('4 доп.сведения'!B72))=0," ",'4 доп.сведения'!B72)
BE142: =Диплом!B7 -> YYYY/Б24
BV146: ='1 Обладатель диплома'!B17 &" "&'1 Обладатель диплома'!B18&" "&'1 Обладатель диплома'!B19&" "&'1 Обладатель диплома'!B20
BE154: =Диплом!B8 -> YY июня 2024 года

Sheet Лист1

Sheet Лист2

Sheet Оборотная24
AE14: =IF(LEN(TRIM('3 Освоение программы'!B68))=0," ",'3 Освоение программы'!B68) -> Дисциплина 67 | AR14: =IF(LEN(TRIM('3 Освоение программы'!C68))=0," ",'3 Освоение программы'!C68) -> ?? з.е. | AV14: =IF(LEN(TRIM('3 Освоение программы'!D68))=0," ",'3 Освоение программы'!D68) -> оценка
AE15: =IF(LEN(TRIM('3 Освоение программы'!B69))=0," ",'3 Освоение программы'!B69) -> Дисциплина 68 | AR15: =IF(LEN(TRIM('3 Освоение программы'!C69))=0," ",'3 Освоение программы'!C69) -> ?? з.е. | AV15: =IF(LEN(TRIM('3 Освоение программы'!D69))=0," ",'3 Освоение программы'!D69) -> оценка
B16: =IF(LEN(TRIM('3 Освоение программы'!B2))=0," ",'3 Освоение программы'!B2) -> Дисциплина 1 | Q16: =IF(LEN(TRIM('3 Освоение программы'!C2))=0," ",'3 Освоение программы'!C2) -> ?? з.е. | V16: =IF(LEN(TRIM('3 Освоение программы'!D2))=0," ",'3 Освоение программы'!D2) -> оценка | AE16: =IF(LEN(TRIM('3 Освоение программы'!B70))=0," ",'3 Освоение программы'!B70) -> Дисциплина 69 | AR16: =IF(LEN(TRIM('3 Освоение программы'!C70))=0," ",'3 Освоение программы'!C70) -> ?? з.е. | AV16: =IF(LEN(TRIM('3 Освоение программы'!D70))=0," ",'3 Освоение программы'!D70) -> оценка
B17: =IF(LEN(TRIM('3 Освоение программы'!B3))=0," ",'3 Освоение программы'!B3) -> Дисциплина 2 | Q17: =IF(LEN(TRIM('3 Освоение программы'!C3))=0," ",'3 Освоение программы'!C3) -> ?? з.е. | V17: =IF(LEN(TRIM('3 Освоение программы'!D3))=0," ",'3 Освоение программы'!D3) -> оценка | AE17: =IF(LEN(TRIM('3 Освоение программы'!B71))=0," ",'3 Освоение программы'!B71) -> Дисциплина 70 | AR17: =IF(LEN(TRIM('3 Освоение программы'!C71))=0," ",'3 Освоение программы'!C71) -> ?? з.е. | AV17: =IF(LEN(TRIM('3 Освоение программы'!D71))=0," ",'3 Освоение программы'!D71) -> оценка
B18: =IF(LEN(TRIM('3 Освоение программы'!B4))=0," ",'3 Освоение программы'!B4) -> Дисциплина 3 | Q18: =IF(LEN(TRIM('3 Освоение программы'!C4))=0," ",'3 Освоение программы'!C4) -> ?? з.е. | V18: =IF(LEN(TRIM('3 Освоение программы'!D4))=0," ",'3 Освоение программы'!D4) -> оценка | AE18: =IF(LEN(TRIM('3 Освоение программы'!B72))=0," ",'3 Освоение программы'!B72) -> Практики | AR18: =IF(LEN(TRIM('3 Освоение программы'!C72))=0," ",'3 Освоение программы'!C72) -> ?? з.е. | AV18: =IF(LEN(TRIM('3 Освоение программы'!D72))=0," ",'3 Освоение программы'!D72) -> x
A19: =IF(LEN(TRIM('3 Освоение программы'!B5))=0," ",'3 Освоение программы'!B5) -> Дисциплина 4 | Q19: =IF(LEN(TRIM('3 Освоение программы'!C5))=0," ",'3 Освоение программы'!C5) -> ?? з.е. | V19: =IF(LEN(TRIM('3 Освоение программы'!D5))=0," ",'3 Освоение программы'!D5) -> оценка | AE19: =IF(LEN(TRIM('3 Освоение программы'!B73))=0," ",'3 Освоение программы'!B73) -> в том числе: | AR19: =IF(LEN(TRIM('3 Освоение программы'!C73))=0," ",'3 Освоение программы'!C73) | AV19: =IF(LEN(TRIM('3 Освоение программы'!D73))=0," ",'3 Освоение программы'!D73)
B20: =IF(LEN(TRIM('3 Освоение программы'!B6))=0," ",'3 Освоение программы'!B6) -> Дисциплина 5 | Q20: =IF(LEN(TRIM('3 Освоение программы'!C6))=0," ",'3 Освоение программы'!C6) -> ?? з.е. | V20: =IF(LEN(TRIM('3 Освоение программы'!D6))=0," ",'3 Освоение программы'!D6) -> оценка | AE20: =IF(LEN(TRIM('3 Освоение программы'!B74))=0," ",'3 Освоение программы'!B74) -> Вид практики, тип практики | AR20: =IF(LEN(TRIM('3 Освоение программы'!C74))=0," ",'3 Освоение программы'!C74) -> ?? з.е. | AV20: =IF(LEN(TRIM('3 Освоение программы'!D74))=0," ",'3 Освоение программы'!D74) -> оценка
B21: =IF(LEN(TRIM('3 Освоение программы'!B7))=0," ",'3 Освоение программы'!B7) -> Дисциплина 6 | Q21: =IF(LEN(TRIM('3 Освоение программы'!C7))=0," ",'3 Освоение программы'!C7) -> ?? з.е. | V21: =IF(LEN(TRIM('3 Освоение программы'!D7))=0," ",'3 Освоение программы'!D7) -> оценка | AE21: =IF(LEN(TRIM('3 Освоение программы'!B75))=0," ",'3 Освоение программы'!B75) -> Вид практики, тип практики | AR21: =IF(LEN(TRIM('3 Освоение программы'!C75))=0," ",'3 Освоение программы'!C75) -> ?? з.е. | AV21: =IF(LEN(TRIM('3 Освоение программы'!D75))=0," ",'3 Освоение программы'!D75) -> оценка
B22: =IF(LEN(TRIM('3 Освоение программы'!B8))=0," ",'3 Освоение программы'!B8) -> Дисциплина 7 | Q22: =IF(LEN(TRIM('3 Освоение программы'!C8))=0," ",'3 Освоение программы'!C8) -> ?? з.е. | V22: =IF(LEN(TRIM('3 Освоение программы'!D8))=0," ",'3 Освоение программы'!D8) -> оценка | AE22: =IF(LEN(TRIM('3 Освоение программы'!B76))=0," ",'3 Освоение программы'!B76) -> Вид практики, тип практики | AR22: =IF(LEN(TRIM('3 Освоение программы'!C76))=0," ",'3 Освоение программы'!C76) -> ?? з.е. | AV22: =IF(LEN(TRIM('3 Освоение программы'!D76))=0," ",'3 Освоение программы'!D76) -> оценка
B23: =IF(LEN(TRIM('3 Освоение программы'!B9))=0," ",'3 Освоение программы'!B9) -> Дисциплина 8 | Q23: =IF(LEN(TRIM('3 Освоение программы'!C9))=0," ",'3 Освоение программы'!C9) -> ?? з.е. | V23: =IF(LEN(TRIM('3 Освоение программы'!D9))=0," ",'3 Освоение программы'!D9) -> оценка | AE23: =IF(LEN(TRIM('3 Освоение программы'!B77))=0," ",'3 Освоение программы'!B77) -> Вид практики, тип практики | AR23: =IF(LEN(TRIM('3 Освоение программы'!C77))=0," ",'3 Освоение программы'!C77) -> ?? з.е. | AV23: =IF(LEN(TRIM('3 Освоение программы'!D77))=0," ",'3 Освоение программы'!D77) -> оценка
B24: =IF(LEN(TRIM('3 Освоение программы'!B10))=0," ",'3 Освоение программы'!B10) -> Дисциплина 9 | Q24: =IF(LEN(TRIM('3 Освоение программы'!C10))=0," ",'3 Освоение программы'!C10) -> ?? з.е. | V24: =IF(LEN(TRIM('3 Освоение программы'!D10))=0," ",'3 Освоение программы'!D10) -> оценка | AE24: =IF(LEN(TRIM('3 Освоение программы'!B78))=0," ",'3 Освоение программы'!B78) -> Вид практики, тип практики | AR24: =IF(LEN(TRIM('3 Освоение программы'!C78))=0," ",'3 Освоение программы'!C78) -> ?? з.е. | AV24: =IF(LEN(TRIM('3 Освоение программы'!D78))=0," ",'3 Освоение программы'!D78) -> оценка
B25: =IF(LEN(TRIM('3 Освоение программы'!B11))=0," ",'3 Освоение программы'!B11) -> Дисциплина 10 | Q25: =IF(LEN(TRIM('3 Освоение программы'!C11))=0," ",'3 Освоение программы'!C11) -> ?? з.е. | V25: =IF(LEN(TRIM('3 Освоение программы'!D11))=0," ",'3 Освоение программы'!D11) -> оценка | AE25: =IF(LEN(TRIM('3 Освоение программы'!B79))=0," ",'3 Освоение программы'!B79) -> Государственная итоговая аттестация | AR25: =IF(LEN(TRIM('3 Освоение программы'!C79))=0," ",'3 Освоение программы'!C79) -> ?? з.е. | AV25: =IF(LEN(TRIM('3 Освоение программы'!D79))=0," ",'3 Освоение программы'!D79) -> х
B26: =IF(LEN(TRIM('3 Освоение программы'!B12))=0," ",'3 Освоение программы'!B12) -> Дисциплина 11 | Q26: =IF(LEN(TRIM('3 Освоение программы'!C12))=0," ",'3 Освоение программы'!C12) -> ?? з.е. | V26: =IF(LEN(TRIM('3 Освоение программы'!D12))=0," ",'3 Освоение программы'!D12) -> оценка | AE26: =IF(LEN(TRIM('3 Освоение программы'!B80))=0," ",'3 Освоение программы'!B80) -> в том числе: | AR26: =IF(LEN(TRIM('3 Освоение программы'!C80))=0," ",'3 Освоение программы'!C80) | AV26: =IF(LEN(TRIM('3 Освоение программы'!D80))=0," ",'3 Освоение программы'!D80)
B27: =IF(LEN(TRIM('3 Освоение программы'!B13))=0," ",'3 Освоение программы'!B13) -> Дисциплина 12 | Q27: =IF(LEN(TRIM('3 Освоение программы'!C13))=0," ",'3 Освоение программы'!C13) -> ?? з.е. | V27: =IF(LEN(TRIM('3 Освоение программы'!D13))=0," ",'3 Освоение программы'!D13) -> оценка | AE27: =IF(LEN(TRIM('3 Освоение программы'!B81))=0," ",'3 Освоение программы'!B81) -> Выпускная квалификационная работа (бакалаврская работа) | AR27: =IF(LEN(TRIM('3 Освоение программы'!C81))=0," ",'3 Освоение программы'!C81) | AV27: =IF(LEN(TRIM('3 Освоение программы'!D81))=0," ",'3 Освоение программы'!D81)
B28: =IF(LEN(TRIM('3 Освоение программы'!B14))=0," ",'3 Освоение программы'!B14) -> Дисциплина 13 | Q28: =IF(LEN(TRIM('3 Освоение программы'!C14))=0," ",'3 Освоение программы'!C14) -> ?? з.е. | V28: =IF(LEN(TRIM('3 Освоение программы'!D14))=0," ",'3 Освоение программы'!D14) -> оценка | AE28: =IF(LEN(TRIM('3 Освоение программы'!B82))=0," ",'3 Освоение программы'!B82) -> "Субъективное благополучие отстающих в обучении | AR28: =IF(LEN(TRIM('3 Освоение программы'!C82))=0," ",'3 Освоение программы'!C82) | AV28: =IF(LEN(TRIM('3 Освоение программы'!D82))=0," ",'3 Освоение программы'!D82)
B29: =IF(LEN(TRIM('3 Освоение программы'!B15))=0," ",'3 Освоение программы'!B15) -> Дисциплина 14 | Q29: =IF(LEN(TRIM('3 Освоение программы'!C15))=0," ",'3 Освоение программы'!C15) -> ?? з.е. | V29: =IF(LEN(TRIM('3 Освоение программы'!D15))=0," ",'3 Освоение программы'!D15) -> оценка | AE29: =IF(LEN(TRIM('3 Освоение программы'!B83))=0," ",'3 Освоение программы'!B83) -> младших школьников" | AR29: =IF(LEN(TRIM('3 Освоение программы'!C83))=0," ",'3 Освоение программы'!C83) -> х | AV29: =IF(LEN(TRIM('3 Освоение программы'!D83))=0," ",'3 Освоение программы'!D83) -> оценка
B30: =IF(LEN(TRIM('3 Освоение программы'!B16))=0," ",'3 Освоение программы'!B16) -> Дисциплина 15 | Q30: =IF(LEN(TRIM('3 Освоение программы'!C16))=0," ",'3 Освоение программы'!C16) -> ?? з.е. | V30: =IF(LEN(TRIM('3 Освоение программы'!D16))=0," ",'3 Освоение программы'!D16) -> оценка | AE30: =IF(LEN(TRIM('3 Освоение программы'!B84))=0," ",'3 Освоение программы'!B84) -> Объем образовательной программы | AR30: =IF(LEN(TRIM('3 Освоение программы'!C84))=0," ",'3 Освоение программы'!C84) -> 240 з.е. | AV30: =IF(LEN(TRIM('3 Освоение программы'!D84))=0," ",'3 Освоение программы'!D84) -> х
B31: =IF(LEN(TRIM('3 Освоение программы'!B17))=0," ",'3 Освоение программы'!B17) -> Дисциплина 16 | Q31: =IF(LEN(TRIM('3 Освоение программы'!C17))=0," ",'3 Освоение программы'!C17) -> ?? з.е. | V31: =IF(LEN(TRIM('3 Освоение программы'!D17))=0," ",'3 Освоение программы'!D17) -> оценка | AE31: =IF(LEN(TRIM('3 Освоение программы'!B85))=0," ",'3 Освоение программы'!B85) -> в том числе объем контактной работы обучающихся | AR31: =IF(LEN(TRIM('3 Освоение программы'!C85))=0," ",'3 Освоение программы'!C85) | AV31: =IF(LEN(TRIM('3 Освоение программы'!D85))=0," ",'3 Освоение программы'!D85)
... B81: =IF(LEN(TRIM('3 Освоение программы'!B67))=0," ",'3 Освоение программы'!B67) -> Дисциплина 66 | Q81: =IF(LEN(TRIM('3 Освоение программы'!C67))=0," ",'3 Освоение программы'!C67) -> ?? з.е. | V81: =IF(LEN(TRIM('3 Освоение программы'!D67))=0," ",'3 Освоение программы'!D67) -> оценка | AE81: =IF(LEN(TRIM('3 Освоение программы'!B135))=0," ",'3 Освоение программы'!B135) | AR81: =IF(LEN(TRIM('3 Освоение программы'!C135))=0," ",'3 Освоение программы'!C135) | AV81: =IF(LEN(TRIM('3 Освоение программы'!D135))=0," ",'3 Освоение программы'!D135)

Sheet Лицевая (2)
CF22: ='1 Обладатель диплома'!B3 -> Фамилия
CF28: ='1 Обладатель диплома'!B4 -> Имя
E29: =IF(LEN(TRIM('4 доп.сведения'!B2))=0," ",'4 доп.сведения'!B2) | AO29: =IF(LEN(TRIM('4 доп.сведения'!C2))=0," ",'4 доп.сведения'!C2)
E31: =IF(LEN(TRIM('4 доп.сведения'!B3))=0," ",'4 доп.сведения'!B3) | AO31: =IF(LEN(TRIM('4 доп.сведения'!C3))=0," ",'4 доп.сведения'!C3)
E33: =IF(LEN(TRIM('4 доп.сведения'!B4))=0," ",'4 доп.сведения'!B4) | AO33: =IF(LEN(TRIM('4 доп.сведения'!C4))=0," ",'4 доп.сведения'!C4)
E35: =IF(LEN(TRIM('4 доп.сведения'!B5))=0," ",'4 доп.сведения'!B5) | AO35: =IF(LEN(TRIM('4 доп.сведения'!C5))=0," ",'4 доп.сведения'!C5) | CF35: ='1 Обладатель диплома'!B5 -> Отчество
E37: =IF(LEN(TRIM('4 доп.сведения'!B6))=0," ",'4 доп.сведения'!B6) | AO37: =IF(LEN(TRIM('4 доп.сведения'!C6))=0," ",'4 доп.сведения'!C6)
E39: =IF(LEN(TRIM('4 доп.сведения'!B7))=0," ",'4 доп.сведения'!B7) | AO39: =IF(LEN(TRIM('4 доп.сведения'!C7))=0," ",'4 доп.сведения'!C7)
E41: =IF(LEN(TRIM('4 доп.сведения'!B8))=0," ",'4 доп.сведения'!B8) | AO41: =IF(LEN(TRIM('4 доп.сведения'!C8))=0," ",'4 доп.сведения'!C8)
CF42: ='1 Обладатель диплома'!B6 -> 22 января 2005 года
E43: =IF(LEN(TRIM('4 доп.сведения'!B9))=0," ",'4 доп.сведения'!B9) | AO43: =IF(LEN(TRIM('4 доп.сведения'!C9))=0," ",'4 доп.сведения'!C9)
E45: =IF(LEN(TRIM('4 доп.сведения'!B10))=0," ",'4 доп.сведения'!B10) | AO45: =IF(LEN(TRIM('4 доп.сведения'!C10))=0," ",'4 доп.сведения'!C10)
E47: =IF(LEN(TRIM('4 доп.сведения'!B11))=0," ",'4 доп.сведения'!B11) | AO47: =IF(LEN(TRIM('4 доп.сведения'!C11))=0," ",'4 доп.сведения'!C11)
E49: =IF(LEN(TRIM('4 доп.сведения'!B12))=0," ",'4 доп.сведения'!B12) | AO49: =IF(LEN(TRIM('4 доп.сведения'!C12))=0," ",'4 доп.сведения'!C12)
E51: =IF(LEN(TRIM('4 доп.сведения'!B13))=0," ",'4 доп.сведения'!B13) | AO51: =IF(LEN(TRIM('4 доп.сведения'!C13))=0," ",'4 доп.сведения'!C13) | BE51: =Диплом!B2 -> федеральное государственное бюджетное образовательное учреждение высшего образования «Московский государственный психолого-педагогический университет»
E53: =IF(LEN(TRIM('4 доп.сведения'!B14))=0," ",'4 доп.сведения'!B14) | AO53: =IF(LEN(TRIM('4 доп.сведения'!C14))=0," ",'4 доп.сведения'!C14)
E55: =IF(LEN(TRIM('4 доп.сведения'!B15))=0," ",'4 доп.сведения'!B15) | AO55: =IF(LEN(TRIM('4 доп.сведения'!C15))=0," ",'4 доп.сведения'!C15)
BW56: =IF(LEN(TRIM('1 Обладатель диплома'!B8 & " " &'1 Обладатель диплома'!B9))=0," ",'1 Обладатель диплома'!B8 & " " &'1 Обладатель диплома'!B9)
E57: =IF(LEN(TRIM('4 доп.сведения'!B16))=0," ",'4 доп.сведения'!B16) | AO57: =IF(LEN(TRIM('4 доп.сведения'!C16))=0," ",'4 доп.сведения'!C16)
E59: =IF(LEN(TRIM('4 доп.сведения'!B17))=0," ",'4 доп.сведения'!B17) | AO59: =IF(LEN(TRIM('4 доп.сведения'!C17))=0," ",'4 доп.сведения'!C17)
E61: =IF(LEN(TRIM('4 доп.сведения'!B18))=0," ",'4 доп.сведения'!B18) | AO61: =IF(LEN(TRIM('4 доп.сведения'!C18))=0," ",'4 доп.сведения'!C18)
E63: =IF(LEN(TRIM('4 доп.сведения'!B19))=0," ",'4 доп.сведения'!B19) | AO63: =IF(LEN(TRIM('4 доп.сведения'!C19))=0," ",'4 доп.сведения'!C19)
E65: =IF(LEN(TRIM('4 доп.сведения'!B20))=0," ",'4 доп.сведения'!B20) | AO65: =IF(LEN(TRIM('4 доп.сведения'!C20))=0," ",'4 доп.сведения'!C20)
E67: =IF(LEN(TRIM('4 доп.сведения'!B21))=0," ",'4 доп.сведения'!B21) | AO67: =IF(LEN(TRIM('4 доп.сведения'!C21))=0," ",'4 доп.сведения'!C21)
E69: =IF(LEN(TRIM('4 доп.сведения'!B22))=0," ",'4 доп.сведения'!B22) | AO69: =IF(LEN(TRIM('4 доп.сведения'!C22))=0," ",'4 доп.сведения'!C22)
E71: =IF(LEN(TRIM('4 доп.сведения'!B23))=0," ",'4 доп.сведения'!B23) | AO71: =IF(LEN(TRIM('4 доп.сведения'!C23))=0," ",'4 доп.сведения'!C23)
E73: =IF(LEN(TRIM('4 доп.сведения'!B24))=0," ",'4 доп.сведения'!B24) | AO73: =IF(LEN(TRIM('4 доп.сведения'!C24))=0," ",'4 доп.сведения'!C24)
E75: =IF(LEN(TRIM('4 доп.сведения'!B25))=0," ",'4 доп.сведения'!B25) | AO75: =IF(LEN(TRIM('4 доп.сведения'!C25))=0," ",'4 доп.сведения'!C25)
E77: =IF(LEN(TRIM('4 доп.сведения'!B26))=0," ",'4 доп.сведения'!B26) | AO77: =IF(LEN(TRIM('4 доп.сведения'!C26))=0," ",'4 доп.сведения'!C26)
E79: =IF(LEN(TRIM('4 доп.сведения'!B27))=0," ",'4 доп.сведения'!B27) | AO79: =IF(LEN(TRIM('4 доп.сведения'!C27))=0," ",'4 доп.сведения'!C27)
E81: =IF(LEN(TRIM('4 доп.сведения'!B28))=0," ",'4 доп.сведения'!B28) | AO81: =IF(LEN(TRIM('4 доп.сведения'!C28))=0," ",'4 доп.сведения'!C28)
E83: =IF(LEN(TRIM('4 доп.сведения'!B29))=0," ",'4 доп.сведения'!B29) | AO83: =IF(LEN(TRIM('4 доп.сведения'!C29))=0," ",'4 доп.сведения'!C29)
E85: =IF(LEN(TRIM('4 доп.сведения'!B30))=0," ",'4 доп.сведения'!B30) | AO85: =IF(LEN(TRIM('4 доп.сведения'!C30))=0," ",'4 доп.сведения'!C30) | BE85: =Диплом!B3 -> г Москва
E87: =IF(LEN(TRIM('4 доп.сведения'!B31))=0," ",'4 доп.сведения'!B31) | AO87: =IF(LEN(TRIM('4 доп.сведения'!C31))=0," ",'4 доп.сведения'!C31)
E89: =IF(LEN(TRIM('4 доп.сведения'!B32))=0," ",'4 доп.сведения'!B32) | AO89: =IF(LEN(TRIM('4 доп.сведения'!C32))=0," ",'4 доп.сведения'!C32)
E91: =IF(LEN(TRIM('4 доп.сведения'!B33))=0," ",'4 доп.сведения'!B33) | AO91: =IF(LEN(TRIM('4 доп.сведения'!C33))=0," ",'4 доп.сведения'!C33)
E93: =IF(LEN(TRIM('4 доп.сведения'!B34))=0," ",'4 доп.сведения'!B34) | AO93: =IF(LEN(TRIM('4 доп.сведения'!C34))=0," ",'4 доп.сведения'!C34)
E95: =IF(LEN(TRIM('4 доп.сведения'!B35))=0," ",'4 доп.сведения'!B35) | AO95: =IF(LEN(TRIM('4 доп.сведения'!C35))=0," ",'4 доп.сведения'!C35)
E97: =IF(LEN(TRIM('4 доп.сведения'!B36))=0," ",'4 доп.сведения'!B36) | AO97: =IF(LEN(TRIM('4 доп.сведения'!C36))=0," ",'4 доп.сведения'!C36)
E99: =IF(LEN(TRIM('4 доп.сведения'!B37))=0," ",'4 доп.сведения'!B37) | AO99: =IF(LEN(TRIM('4 доп.сведения'!C37))=0," ",'4 доп.сведения'!C37)
...

Sheet Оборотная (2)
AE13: =IF(LEN(TRIM('3 Освоение программы'!B67))=0," ",'3 Освоение программы'!B67) -> Дисциплина 66 | AR13: =IF(LEN(TRIM('3 Освоение программы'!C67))=0," ",'3 Освоение программы'!C67) -> ?? з.е. | AW13: =IF(LEN(TRIM('3 Освоение программы'!D67))=0," ",'3 Освоение программы'!D67) -> оценка
AE14: =IF(LEN(TRIM('3 Освоение программы'!B68))=0," ",'3 Освоение программы'!B68) -> Дисциплина 67 | AR14: =IF(LEN(TRIM('3 Освоение программы'!C68))=0," ",'3 Освоение программы'!C68) -> ?? з.е. | AW14: =IF(LEN(TRIM('3 Освоение программы'!D68))=0," ",'3 Освоение программы'!D68) -> оценка
AE15: =IF(LEN(TRIM('3 Освоение программы'!B69))=0," ",'3 Освоение программы'!B69) -> Дисциплина 68 | AR15: =IF(LEN(TRIM('3 Освоение программы'!C69))=0," ",'3 Освоение программы'!C69) -> ?? з.е. | AW15: =IF(LEN(TRIM('3 Освоение программы'!D69))=0," ",'3 Освоение программы'!D69) -> оценка
C16: =IF(LEN(TRIM('3 Освоение программы'!B2))=0," ",'3 Освоение программы'!B2) -> Дисциплина 1 | P16: =IF(LEN(TRIM('3 Освоение программы'!C2))=0," ",'3 Освоение программы'!C2) -> ?? з.е. | U16: =IF(LEN(TRIM('3 Освоение программы'!D2))=0," ",'3 Освоение программы'!D2) -> оценка | AE16: =IF(LEN(TRIM('3 Освоение программы'!B70))=0," ",'3 Освоение программы'!B70) -> Дисциплина 69 | AR16: =IF(LEN(TRIM('3 Освоение программы'!C70))=0," ",'3 Освоение программы'!C70) -> ?? з.е. | AW16: =IF(LEN(TRIM('3 Освоение программы'!D70))=0," ",'3 Освоение программы'!D70) -> оценка
C17: =IF(LEN(TRIM('3 Освоение программы'!B3))=0," ",'3 Освоение программы'!B3) -> Дисциплина 2 | P17: =IF(LEN(TRIM('3 Освоение программы'!C3))=0," ",'3 Освоение программы'!C3) -> ?? з.е. | U17: =IF(LEN(TRIM('3 Освоение программы'!D3))=0," ",'3 Освоение программы'!D3) -> оценка | AE17: =IF(LEN(TRIM('3 Освоение программы'!B71))=0," ",'3 Освоение программы'!B71) -> Дисциплина 70 | AR17: =IF(LEN(TRIM('3 Освоение программы'!C71))=0," ",'3 Освоение программы'!C71) -> ?? з.е. | AW17: =IF(LEN(TRIM('3 Освоение программы'!D71))=0," ",'3 Освоение программы'!D71) -> оценка
C18: =IF(LEN(TRIM('3 Освоение программы'!B4))=0," ",'3 Освоение программы'!B4) -> Дисциплина 3 | P18: =IF(LEN(TRIM('3 Освоение программы'!C4))=0," ",'3 Освоение программы'!C4) -> ?? з.е. | U18: =IF(LEN(TRIM('3 Освоение программы'!D4))=0," ",'3 Освоение программы'!D4) -> оценка | AE18: =IF(LEN(TRIM('3 Освоение программы'!B72))=0," ",'3 Освоение программы'!B72) -> Практики | AR18: =IF(LEN(TRIM('3 Освоение программы'!C72))=0," ",'3 Освоение программы'!C72) -> ?? з.е. | AW18: =IF(LEN(TRIM('3 Освоение программы'!D72))=0," ",'3 Освоение программы'!D72) -> x
C19: =IF(LEN(TRIM('3 Освоение программы'!B5))=0," ",'3 Освоение программы'!B5) -> Дисциплина 4 | P19: =IF(LEN(TRIM('3 Освоение программы'!C5))=0," ",'3 Освоение программы'!C5) -> ?? з.е. | U19: =IF(LEN(TRIM('3 Освоение программы'!D5))=0," ",'3 Освоение программы'!D5) -> оценка | AE19: =IF(LEN(TRIM('3 Освоение программы'!B73))=0," ",'3 Освоение программы'!B73) -> в том числе: | AR19: =IF(LEN(TRIM('3 Освоение программы'!C73))=0," ",'3 Освоение программы'!C73) | AW19: =IF(LEN(TRIM('3 Освоение программы'!D73))=0," ",'3 Освоение программы'!D73)
C20: =IF(LEN(TRIM('3 Освоение программы'!B6))=0," ",'3 Освоение программы'!B6) -> Дисциплина 5 | P20: =IF(LEN(TRIM('3 Освоение программы'!C6))=0," ",'3 Освоение программы'!C6) -> ?? з.е. | U20: =IF(LEN(TRIM('3 Освоение программы'!D6))=0," ",'3 Освоение программы'!D6) -> оценка | AE20: =IF(LEN(TRIM('3 Освоение программы'!B74))=0," ",'3 Освоение программы'!B74) -> Вид практики, тип практики | AR20: =IF(LEN(TRIM('3 Освоение программы'!C74))=0," ",'3 Освоение программы'!C74) -> ?? з.е. | AW20: =IF(LEN(TRIM('3 Освоение программы'!D74))=0," ",'3 Освоение программы'!D74) -> оценка
C21: =IF(LEN(TRIM('3 Освоение программы'!B7))=0," ",'3 Освоение программы'!B7) -> Дисциплина 6 | P21: =IF(LEN(TRIM('3 Освоение программы'!C7))=0," ",'3 Освоение программы'!C7) -> ?? з.е. | U21: =IF(LEN(TRIM('3 Освоение программы'!D7))=0," ",'3 Освоение программы'!D7) -> оценка | AE21: =IF(LEN(TRIM('3 Освоение программы'!B75))=0," ",'3 Освоение программы'!B75) -> Вид практики, тип практики | AR21: =IF(LEN(TRIM('3 Освоение программы'!C75))=0," ",'3 Освоение программы'!C75) -> ?? з.е. | AW21: =IF(LEN(TRIM('3 Освоение программы'!D75))=0," ",'3 Освоение программы'!D75) -> оценка
C22: =IF(LEN(TRIM('3 Освоение программы'!B8))=0," ",'3 Освоение программы'!B8) -> Дисциплина 7 | P22: =IF(LEN(TRIM('3 Освоение программы'!C8))=0," ",'3 Освоение программы'!C8) -> ?? з.е. | U22: =IF(LEN(TRIM('3 Освоение программы'!D8))=0," ",'3 Освоение программы'!D8) -> оценка | AE22: =IF(LEN(TRIM('3 Освоение программы'!B76))=0," ",'3 Освоение программы'!B76) -> Вид практики, тип практики | AR22: =IF(LEN(TRIM('3 Освоение программы'!C76))=0," ",'3 Освоение программы'!C76) -> ?? з.е. | AW22: =IF(LEN(TRIM('3 Освоение программы'!D76))=0," ",'3 Освоение программы'!D76) -> оценка
C23: =IF(LEN(TRIM('3 Освоение программы'!B9))=0," ",'3 Освоение программы'!B9) -> Дисциплина 8 | P23: =IF(LEN(TRIM('3 Освоение программы'!C9))=0," ",'3 Освоение программы'!C9) -> ?? з.е. | U23: =IF(LEN(TRIM('3 Освоение программы'!D9))=0," ",'3 Освоение программы'!D9) -> оценка | AE23: =IF(LEN(TRIM('3 Освоение программы'!B77))=0," ",'3 Освоение программы'!B77) -> Вид практики, тип практики | AR23: =IF(LEN(TRIM('3 Освоение программы'!C77))=0," ",'3 Освоение программы'!C77) -> ?? з.е. | AW23: =IF(LEN(TRIM('3 Освоение программы'!D77))=0," ",'3 Освоение программы'!D77) -> оценка
C24: =IF(LEN(TRIM('3 Освоение программы'!B10))=0," ",'3 Освоение программы'!B10) -> Дисциплина 9 | P24: =IF(LEN(TRIM('3 Освоение программы'!C10))=0," ",'3 Освоение программы'!C10) -> ?? з.е. | U24: =IF(LEN(TRIM('3 Освоение программы'!D10))=0," ",'3 Освоение программы'!D10) -> оценка | AE24: =IF(LEN(TRIM('3 Освоение программы'!B78))=0," ",'3 Освоение программы'!B78) -> Вид практики, тип практики | AR24: =IF(LEN(TRIM('3 Освоение программы'!C78))=0," ",'3 Освоение программы'!C78) -> ?? з.е. | AW24: =IF(LEN(TRIM('3 Освоение программы'!D78))=0," ",'3 Освоение программы'!D78) -> оценка
C25: =IF(LEN(TRIM('3 Освоение программы'!B11))=0," ",'3 Освоение программы'!B11) -> Дисциплина 10 | P25: =IF(LEN(TRIM('3 Освоение программы'!C11))=0," ",'3 Освоение программы'!C11) -> ?? з.е. | U25: =IF(LEN(TRIM('3 Освоение программы'!D11))=0," ",'3 Освоение программы'!D11) -> оценка | AE25: =IF(LEN(TRIM('3 Освоение программы'!B79))=0," ",'3 Освоение программы'!B79) -> Государственная итоговая аттестация | AR25: =IF(LEN(TRIM('3 Освоение программы'!C79))=0," ",'3 Освоение программы'!C79) -> ?? з.е. | AW25: =IF(LEN(TRIM('3 Освоение программы'!D79))=0," ",'3 Освоение программы'!D79) -> х
C26: =IF(LEN(TRIM('3 Освоение программы'!B12))=0," ",'3 Освоение программы'!B12) -> Дисциплина 11 | P26: =IF(LEN(TRIM('3 Освоение программы'!C12))=0," ",'3 Освоение программы'!C12) -> ?? з.е. | U26: =IF(LEN(TRIM('3 Освоение программы'!D12))=0," ",'3 Освоение программы'!D12) -> оценка | AE26: =IF(LEN(TRIM('3 Освоение программы'!B80))=0," ",'3 Освоение программы'!B80) -> в том числе: | AR26: =IF(LEN(TRIM('3 Освоение программы'!C80))=0," ",'3 Освоение программы'!C80) | AW26: =IF(LEN(TRIM('3 Освоение программы'!D80))=0," ",'3 Освоение программы'!D80)
C27: =IF(LEN(TRIM('3 Освоение программы'!B13))=0," ",'3 Освоение программы'!B13) -> Дисциплина 12 | P27: =IF(LEN(TRIM('3 Освоение программы'!C13))=0," ",'3 Освоение программы'!C13) -> ?? з.е. | U27: =IF(LEN(TRIM('3 Освоение программы'!D13))=0," ",'3 Освоение программы'!D13) -> оценка | AE27: =IF(LEN(TRIM('3 Освоение программы'!B81))=0," ",'3 Освоение программы'!B81) -> Выпускная квалификационная работа (бакалаврская работа) | AR27: =IF(LEN(TRIM('3 Освоение программы'!C81))=0," ",'3 Освоение программы'!C81) | AW27: =IF(LEN(TRIM('3 Освоение программы'!D81))=0," ",'3 Освоение программы'!D81)
... C80: =IF(LEN(TRIM('3 Освоение программы'!B66))=0," ",'3 Освоение программы'!B66) -> Дисциплина 65 | P80: =IF(LEN(TRIM('3 Освоение программы'!C66))=0," ",'3 Освоение программы'!C66) -> ?? з.е. | U80: =IF(LEN(TRIM('3 Освоение программы'!D66))=0," ",'3 Освоение программы'!D66) -> оценка | AE80: =IF(LEN(TRIM('3 Освоение программы'!B134))=0," ",'3 Освоение программы'!B134) | AR80: =IF(LEN(TRIM('3 Освоение программы'!C134))=0," ",'3 Освоение программы'!C134) | AW80: =IF(LEN(TRIM('3 Освоение программы'!D134))=0," ",'3 Освоение программы'!D134)
